<mujoco model="dog_v2">
  <compiler angle="radian" autolimits="true" eulerseq="zyx" meshdir="meshes" />
  <option gravity='0 0 -9.81'>
    <flag frictionloss="enable"/>
  </option>
  <size njmax="500" nconmax="100" />

  <default>
    <joint limited="true" />
    <motor ctrllimited="true" />
    <geom condim="1" contype="1" conaffinity="0" friction="0.6 0.2 0.2" />
    <default class="leg_joint_param">
      <joint damping="0.5" frictionloss="0.01" armature="0.01" />
    </default>
    <default class="foot_collision">
      <geom type="sphere" size="0.02" condim="6" friction="10.0 0.05 0.01"/>
    </default>
  </default>

  <asset>
    <mesh name="base_link" file="base_link.STL" />
    <mesh name="LF_HipA_link" file="LF_HipA_link.STL" />
    <mesh name="LF_HipF_link" file="LF_HipF_link.STL" />
    <mesh name="LF_Knee_link" file="LF_Knee_link.STL" />
    <mesh name="LF_Foot_link" file="LF_Foot_link.STL" />
    <mesh name="RF_HipA_link" file="RF_HipA_link.STL" />
    <mesh name="RF_HipF_link" file="RF_HipF_link.STL" />
    <mesh name="RF_Knee_link" file="RF_Knee_link.STL" />
    <mesh name="RF_Foot_link" file="RF_Foot_link.STL" />
    <mesh name="LR_HipA_link" file="LR_HipA_link.STL" />
    <mesh name="LR_HipF_link" file="LR_HipF_link.STL" />
    <mesh name="LR_Knee_link" file="LR_Knee_link.STL" />
    <mesh name="LR_Foot_link" file="LR_Foot_link.STL" />
    <mesh name="RR_HipA_link" file="RR_HipA_link.STL" />
    <mesh name="RR_HipF_link" file="RR_HipF_link.STL" />
    <mesh name="RR_Knee_link" file="RR_Knee_link.STL" />
    <mesh name="RR_Foot_link" file="RR_Foot_link.STL" />
  </asset>

  <worldbody>
    <light directional="true" diffuse=".4 .4 .4" pos="0 0 5.0" dir="0 0 -1"/>

    <body name="base" pos="0 0 0.45">
      <freejoint name="floating_base" />
      <inertial pos="0.003073 -1.1e-05 0.058211" mass="5.276437" fullinertia="0.032842099924 0.103762167556 0.116538404566 3.336928e-05 -0.007254554244 3.335365e-05" />
      <site name="imu" size="0.01" pos="0 0 0" />
      <!-- <geom name="base" type="mesh" mesh="base_link" rgba="0.75294 0.75294 0.75294 1" contype="0" conaffinity="0" group="1" /> -->
      <geom name="base" type="mesh" mesh="base_link" rgba="0.75294 0.75294 0.75294 1" group="1" />

      <body name="FL_hip" pos="0.16 0.0674994572689366 0.0630000490222146" quat="0.499999999999998 0.5 0.500000000000002 0.5">
        <inertial pos="0.002621 5.2e-05 0.046852" mass="0.452382" fullinertia="0.00055866874 0.000347032635 0.000308951038 3.41744e-07 -7.08495e-07 -9.1476e-08" />
        <joint name="FL_hip_joint" axis="0 0 1" range="-0.7853982 0.7853982" class="leg_joint_param" />
        <geom name="FL_hip" type="mesh" mesh="LF_HipA_link" rgba="0.752941176470588 0.752941176470588 0.752941176470588 1" group="1" />
        <body name="FL_thigh" pos="0.018001 0 0.048001" quat="0.707105482511236 0 0.707108079859474 0">
          <inertial pos="0.033261 -0.016881 0.050217" mass="0.779164" fullinertia="0.001597433226 0.003268376129 0.004330433943 0.001505087455 -0.000442930553 0.000224661879" />
          <joint name="FL_thigh_joint" axis="0 0 1" range="-1.2217658 1.2217658" class="leg_joint_param" />
          <geom name="FL_thigh" type="mesh" mesh="LF_HipF_link" rgba="0.752941176470588 0.752941176470588 0.752941176470588 1" group="1" />
          <body name="FL_calf" pos="0.170743431939306 -0.122257424197791 0.0500000000000068">
            <inertial pos="-0.055107 -0.080197 0.016515" mass="0.121558" fullinertia="0.000549292448 0.000223695708 0.000769619177 -0.000333360171 -1.07893e-07 -1.88213e-07" />
            <joint name="FL_calf_joint" axis="0 0 1" range="-1.2217299 0.69813" class="leg_joint_param" />
            <geom name="FL_calf" type="mesh" mesh="LF_Knee_link" rgba="1 1 1 1" group="1" />
            <site name="FL_foot_site" pos="-0.110125305788291 -0.190742624824423 0.0165" size="0.01" />
            <geom name="FL_foot_visual" type="mesh" mesh="LF_Foot_link" pos="-0.110125305788291 -0.190742624824423 0.0165" quat="0 0 0.707 0.707" contype="0" conaffinity="0" group="1" />
            <geom name="FL_foot_collision" class="foot_collision" pos="-0.110125305788291 -0.190742624824423 0.0165" rgba="0 0 0 0" />
          </body>
        </body>
      </body>

      <body name="FR_hip" pos="0.16 -0.0674994572689349 0.0629999509777826" quat="0.499999999999998 0.5 0.500000000000002 0.5">
        <inertial pos="-0.002621 -5.2e-05 0.046852" mass="0.452382" fullinertia="0.00055866874 0.000347032635 0.000308951038 3.41744e-07 7.08495e-07 9.1476e-08" />
        <joint name="FR_hip_joint" axis="0 0 1" range="-0.7853982 0.7853982" class="leg_joint_param" />
        <geom name="FR_hip" type="mesh" mesh="RF_HipA_link" rgba="0.752941176470588 0.752941176470588 0.752941176470588 1" group="1" />
        <body name="FR_thigh" pos="-0.018001 0 0.048001" quat="0.707105482511236 0 -0.707108079859474 0">
          <inertial pos="-0.033247 -0.016939 0.050217" mass="0.779164" fullinertia="0.001595827327 0.00326915934 0.004329611254 -0.001503634909 0.000443182676 0.000223603548" />
          <joint name="FR_thigh_joint" axis="0 0 1" range="-1.2217342 1.2217342" class="leg_joint_param" />
          <geom name="FR_thigh" type="mesh" mesh="RF_HipF_link" rgba="0.898039215686275 0.917647058823529 0.929411764705882 1" group="1" />
          <body name="FR_calf" pos="-0.17074 -0.12226 0.05">
            <inertial pos="0.055107 -0.080197 0.016485" mass="0.121558" fullinertia="0.000549292448 0.000223695708 0.000769619177 0.000333360171 -1.07893e-07 1.88213e-07" />
            <joint name="FR_calf_joint" axis="0 0 1" range="-0.6981312 1.2217287" class="leg_joint_param" />
            <geom name="FR_calf" type="mesh" mesh="RF_Knee_link" rgba="1 1 1 1" group="1" />
            <site name="FR_foot_site" pos="0.110125305788291 -0.190742624824423 0.0165" size="0.01" />
            <geom name="FR_foot_visual" type="mesh" mesh="RF_Foot_link" pos="0.110125305788291 -0.190742624824423 0.0165" quat="0.707 -0.707 0 0" contype="0" conaffinity="0" group="1" />
            <geom name="FR_foot_collision" class="foot_collision" pos="0.110125305788291 -0.190742624824423 0.0165" rgba="0 0 0 0" />
          </body>
        </body>
      </body>

      <body name="RL_hip" pos="-0.16 0.0674994572689466 0.0629999509777641" quat="0.499999999999998 0.5 -0.500000000000002 -0.5">
        <inertial pos="-0.002621 -5.2e-05 0.046852" mass="0.452382" fullinertia="0.00055866874 0.000347032635 0.000308951038 3.41744e-07 7.08495e-07 9.1476e-08" />
        <joint name="RL_hip_joint" axis="0 0 1" range="-0.7853982 0.7853982" class="leg_joint_param" />
        <geom name="RL_hip" type="mesh" mesh="LR_HipA_link" rgba="0.752941176470588 0.752941176470588 0.752941176470588 1" group="1" />
        <body name="RL_thigh" pos="-0.018001 0 0.048001" quat="0.707105482511236 0 -0.707108079859474 0">
          <inertial pos="0.03326 -0.016881 0.050217" mass="0.779164" fullinertia="0.001597433226 0.003268376129 0.004330433943 0.001505087455 -0.000442930553 0.000224661879" />
          <joint name="RL_thigh_joint" axis="0 0 1" range="-1.2217305 1.2217305" class="leg_joint_param" />
          <geom name="RL_thigh" type="mesh" mesh="LR_HipF_link" rgba="0.752941176470588 0.752941176470588 0.752941176470588 1" group="1" />
          <body name="RL_calf" pos="0.17074234647718 -0.122257326153361 0.050000000000001">
            <inertial pos="-0.055107 -0.080197 0.016515" mass="0.121558" fullinertia="0.000549292448 0.000223695708 0.000769619177 -0.000333360171 -1.07893e-07 -1.88213e-07" />
            <joint name="RL_calf_joint" axis="0 0 1" range="-1.2217299 0.69813" class="leg_joint_param" />
            <geom name="RL_calf" type="mesh" mesh="LR_Knee_link" rgba="1 1 1 1" group="1" />
            <site name="RL_foot_site" pos="-0.110125305788291 -0.190742624824423 0.0165" size="0.01" />
            <geom name="RL_foot_visual" type="mesh" mesh="LR_Foot_link" pos="-0.110125305788291 -0.190742624824423 0.0165" quat="0 0 -0.707 -0.707" contype="0" conaffinity="0" group="1" />
            <geom name="RL_foot_collision" class="foot_collision" pos="-0.110125305788291 -0.190742624824423 0.0165" rgba="0 0 0 0" />
          </body>
        </body>
      </body>

      <body name="RR_hip" pos="-0.16 -0.0674994572689364 0.0630000490222165" quat="0.499999999999998 0.5 -0.500000000000002 -0.5">
        <inertial pos="0.002621 5.2e-05 0.046852" mass="0.452382" fullinertia="0.00055866874 0.000347032635 0.000308951038 3.41744e-07 -7.08495e-07 -9.1476e-08" />
        <joint name="RR_hip_joint" axis="0 0 1" range="-0.7853982 0.7853982" class="leg_joint_param" />
        <geom name="RR_hip" type="mesh" mesh="RR_HipA_link" rgba="1 1 1 1" group="1" />
        <body name="RR_thigh" pos="0.018001 0 0.048001" quat="0.707105482511236 0 0.707108079859474 0">
          <inertial pos="-0.033246 -0.01694 0.050217" mass="0.779164" fullinertia="0.001595827327 0.00326915934 0.004329611254 -0.001503634909 0.000443182676 0.000223603548" />
          <joint name="RR_thigh_joint" axis="0 0 1" range="-1.2217305 1.2217305" class="leg_joint_param" />
          <geom name="RR_thigh" type="mesh" mesh="RR_HipF_link" rgba="0.752941176470588 0.752941176470588 0.752941176470588 1" group="1" />
          <body name="RR_calf" pos="-0.170742346477182 -0.122257424197793 0.050000000000007">
            <inertial pos="0.055107 -0.080197 0.016485" mass="0.121558" fullinertia="0.000549292448 0.000223695708 0.000769619177 0.000333360171 -1.07893e-07 1.88213e-07" />
            <joint name="RR_calf_joint" axis="0 0 1" range="-0.6981312 1.2217287" class="leg_joint_param" />
            <geom name="RR_calf" type="mesh" mesh="RR_Knee_link" rgba="1 1 1 1" group="1" />
            <site name="RR_foot_site" pos="0.11013 -0.19074 0.0165" size="0.01" />
            <geom name="RR_foot_visual" type="mesh" mesh="RR_Foot_link" pos="0.11013 -0.19074 0.0165" quat="0.707 -0.707 0 0" contype="0" conaffinity="0" group="1" />
            <geom name="RR_foot_collision" class="foot_collision" pos="0.11013 -0.19074 0.0165" rgba="0 0 0 0" />
          </body>
        </body>
      </body>
    </body>
  </worldbody>

  <actuator>
    <motor name="FL_hip" joint="FL_hip_joint" gear="1" ctrllimited="true" ctrlrange="-17 17" />
    <motor name="FL_thigh" joint="FL_thigh_joint" gear="1" ctrllimited="true" ctrlrange="-17 17" />
    <motor name="FL_calf" joint="FL_calf_joint" gear="1" ctrllimited="true" ctrlrange="-25 25" />
    <motor name="FR_hip" joint="FR_hip_joint" gear="1" ctrllimited="true" ctrlrange="-17 17" />
    <motor name="FR_thigh" joint="FR_thigh_joint" gear="1" ctrllimited="true" ctrlrange="-17 17" />
    <motor name="FR_calf" joint="FR_calf_joint" gear="1" ctrllimited="true" ctrlrange="-25 25" />
    <motor name="RL_hip" joint="RL_hip_joint" gear="1" ctrllimited="true" ctrlrange="-17 17" />
    <motor name="RL_thigh" joint="RL_thigh_joint" gear="1" ctrllimited="true" ctrlrange="-17 17" />
    <motor name="RL_calf" joint="RL_calf_joint" gear="1" ctrllimited="true" ctrlrange="-25 25" />
    <motor name="RR_hip" joint="RR_hip_joint" gear="1" ctrllimited="true" ctrlrange="-17 17" />
    <motor name="RR_thigh" joint="RR_thigh_joint" gear="1" ctrllimited="true" ctrlrange="-17 17" />
    <motor name="RR_calf" joint="RR_calf_joint" gear="1" ctrllimited="true" ctrlrange="-25 25" />
  </actuator>

  <sensor>
    <jointpos name="FL_hip_pos" joint="FL_hip_joint"/>
    <jointpos name="FL_thigh_pos" joint="FL_thigh_joint"/>
    <jointpos name="FL_calf_pos" joint="FL_calf_joint"/>
    <jointpos name="FR_hip_pos" joint="FR_hip_joint"/>
    <jointpos name="FR_thigh_pos" joint="FR_thigh_joint"/>
    <jointpos name="FR_calf_pos" joint="FR_calf_joint"/>
    <jointpos name="RL_hip_pos" joint="RL_hip_joint"/>
    <jointpos name="RL_thigh_pos" joint="RL_thigh_joint"/>
    <jointpos name="RL_calf_pos" joint="RL_calf_joint"/>
    <jointpos name="RR_hip_pos" joint="RR_hip_joint"/>
    <jointpos name="RR_thigh_pos" joint="RR_thigh_joint"/>
    <jointpos name="RR_calf_pos" joint="RR_calf_joint"/>

    <jointvel name="FL_hip_vel" joint="FL_hip_joint"/>
    <jointvel name="FL_thigh_vel" joint="FL_thigh_joint"/>
    <jointvel name="FL_calf_vel" joint="FL_calf_joint"/>
    <jointvel name="FR_hip_vel" joint="FR_hip_joint"/>
    <jointvel name="FR_thigh_vel" joint="FR_thigh_joint"/>
    <jointvel name="FR_calf_vel" joint="FR_calf_joint"/>
    <jointvel name="RL_hip_vel" joint="RL_hip_joint"/>
    <jointvel name="RL_thigh_vel" joint="RL_thigh_joint"/>
    <jointvel name="RL_calf_vel" joint="RL_calf_joint"/>
    <jointvel name="RR_hip_vel" joint="RR_hip_joint"/>
    <jointvel name="RR_thigh_vel" joint="RR_thigh_joint"/>
    <jointvel name="RR_calf_vel" joint="RR_calf_joint"/>

    <jointactuatorfrc name="FL_hip_torque" joint="FL_hip_joint"/>
    <jointactuatorfrc name="FL_thigh_torque" joint="FL_thigh_joint"/>
    <jointactuatorfrc name="FL_calf_torque" joint="FL_calf_joint"/>
    <jointactuatorfrc name="FR_hip_torque" joint="FR_hip_joint"/>
    <jointactuatorfrc name="FR_thigh_torque" joint="FR_thigh_joint"/>
    <jointactuatorfrc name="FR_calf_torque" joint="FR_calf_joint"/>
    <jointactuatorfrc name="RL_hip_torque" joint="RL_hip_joint"/>
    <jointactuatorfrc name="RL_thigh_torque" joint="RL_thigh_joint"/>
    <jointactuatorfrc name="RL_calf_torque" joint="RL_calf_joint"/>
    <jointactuatorfrc name="RR_hip_torque" joint="RR_hip_joint"/>
    <jointactuatorfrc name="RR_thigh_torque" joint="RR_thigh_joint"/>
    <jointactuatorfrc name="RR_calf_torque" joint="RR_calf_joint"/>

    <framequat name="orientation" objtype="site" objname="imu"/>
    <gyro name="angular-velocity" site="imu"/>
    <accelerometer name="linear-acceleration" site="imu"/>
    <framepos name="position" objtype="site" objname="imu"/>
  </sensor>
</mujoco>
